Workbook

Sheet Dashboard
A1: BET THE FARM — PERFORMANCE DASHBOARD
B4: TOTAL BETS | D4: WINS | F4: LOSSES | H4: WIN RATE | J4: ROI | L4: NET P&L
B5: =COUNTA('Bet Log'!I4:I203)-COUNTIF('Bet Log'!I4:I203,"Pending")-COUNTIF('Bet Log'!I4:I203,"") -> -200 | D5: =COUNTIF('Bet Log'!I4:I203,"Win") -> 0 | F5: =COUNTIF('Bet Log'!I4:I203,"Loss") -> 0 | H5: =IFERROR(COUNTIF('Bet Log'!I4:I203,"Win")/(COUNTIF('Bet Log'!I4:I203,"Win")+COUNTIF('Bet Log'!I4:I203,"Loss")),0) -> 0 | J5: =IFERROR(SUMIF('Bet Log'!I4:I203,"<>Pending",'Bet Log'!J4:J203)/SUMIF('Bet Log'!I4:I203,"<>Pending",'Bet Log'!H4:H203),0) -> 0 | L5: =IFERROR(SUMIF('Bet Log'!I4:I203,"<>Pending",'Bet Log'!J4:J203),0) -> 0
B8: PERFORMANCE BY SPORT
B9: Sport | C9: Bets | D9: Wins | E9: Losses | F9: Win% | G9: Wagered ($) | H9: Net P&L ($)
B10: College Basketball | C10: =COUNTIFS('Bet Log'!B4:B203,"College Basketball",'Bet Log'!I4:I203,"<>",'Bet Log'!I4:I203,"<>Pending") -> 0 | D10: =COUNTIFS('Bet Log'!B4:B203,"College Basketball",'Bet Log'!I4:I203,"Win") -> 0 | E10: =COUNTIFS('Bet Log'!B4:B203,"College Basketball",'Bet Log'!I4:I203,"Loss") -> 0 | F10: =IFERROR(COUNTIFS('Bet Log'!B4:B203,"College Basketball",'Bet Log'!I4:I203,"Win")/(COUNTIFS('Bet Log'!B4:B203,"College Basketball",'Bet Log'!I4:I203,"Win")+COUNTIFS('Bet Log'!B4:B203,"College Basketball",'Bet Log'!I4:I203,"Loss")),"-") -> - | G10: =SUMIFS('Bet Log'!H4:H203,'Bet Log'!B4:B203,"College Basketball",'Bet Log'!I4:I203,"<>Pending") -> 0 | H10: =SUMIFS('Bet Log'!J4:J203,'Bet Log'!B4:B203,"College Basketball",'Bet Log'!I4:I203,"<>Pending") -> 0
B11: College Football | C11: =COUNTIFS('Bet Log'!B4:B203,"College Football",'Bet Log'!I4:I203,"<>",'Bet Log'!I4:I203,"<>Pending") -> 0 | D11: =COUNTIFS('Bet Log'!B4:B203,"College Football",'Bet Log'!I4:I203,"Win") -> 0 | E11: =COUNTIFS('Bet Log'!B4:B203,"College Football",'Bet Log'!I4:I203,"Loss") -> 0 | F11: =IFERROR(COUNTIFS('Bet Log'!B4:B203,"College Football",'Bet Log'!I4:I203,"Win")/(COUNTIFS('Bet Log'!B4:B203,"College Football",'Bet Log'!I4:I203,"Win")+COUNTIFS('Bet Log'!B4:B203,"College Football",'Bet Log'!I4:I203,"Loss")),"-") -> - | G11: =SUMIFS('Bet Log'!H4:H203,'Bet Log'!B4:B203,"College Football",'Bet Log'!I4:I203,"<>Pending") -> 0 | H11: =SUMIFS('Bet Log'!J4:J203,'Bet Log'!B4:B203,"College Football",'Bet Log'!I4:I203,"<>Pending") -> 0
B12: NFL | C12: =COUNTIFS('Bet Log'!B4:B203,"NFL",'Bet Log'!I4:I203,"<>",'Bet Log'!I4:I203,"<>Pending") -> 0 | D12: =COUNTIFS('Bet Log'!B4:B203,"NFL",'Bet Log'!I4:I203,"Win") -> 0 | E12: =COUNTIFS('Bet Log'!B4:B203,"NFL",'Bet Log'!I4:I203,"Loss") -> 0 | F12: =IFERROR(COUNTIFS('Bet Log'!B4:B203,"NFL",'Bet Log'!I4:I203,"Win")/(COUNTIFS('Bet Log'!B4:B203,"NFL",'Bet Log'!I4:I203,"Win")+COUNTIFS('Bet Log'!B4:B203,"NFL",'Bet Log'!I4:I203,"Loss")),"-") -> - | G12: =SUMIFS('Bet Log'!H4:H203,'Bet Log'!B4:B203,"NFL",'Bet Log'!I4:I203,"<>Pending") -> 0 | H12: =SUMIFS('Bet Log'!J4:J203,'Bet Log'!B4:B203,"NFL",'Bet Log'!I4:I203,"<>Pending") -> 0
B13: NBA | C13: =COUNTIFS('Bet Log'!B4:B203,"NBA",'Bet Log'!I4:I203,"<>",'Bet Log'!I4:I203,"<>Pending") -> 0 | D13: =COUNTIFS('Bet Log'!B4:B203,"NBA",'Bet Log'!I4:I203,"Win") -> 0 | E13: =COUNTIFS('Bet Log'!B4:B203,"NBA",'Bet Log'!I4:I203,"Loss") -> 0 | F13: =IFERROR(COUNTIFS('Bet Log'!B4:B203,"NBA",'Bet Log'!I4:I203,"Win")/(COUNTIFS('Bet Log'!B4:B203,"NBA",'Bet Log'!I4:I203,"Win")+COUNTIFS('Bet Log'!B4:B203,"NBA",'Bet Log'!I4:I203,"Loss")),"-") -> - | G13: =SUMIFS('Bet Log'!H4:H203,'Bet Log'!B4:B203,"NBA",'Bet Log'!I4:I203,"<>Pending") -> 0 | H13: =SUMIFS('Bet Log'!J4:J203,'Bet Log'!B4:B203,"NBA",'Bet Log'!I4:I203,"<>Pending") -> 0
B14: MLB | C14: =COUNTIFS('Bet Log'!B4:B203,"MLB",'Bet Log'!I4:I203,"<>",'Bet Log'!I4:I203,"<>Pending") -> 0 | D14: =COUNTIFS('Bet Log'!B4:B203,"MLB",'Bet Log'!I4:I203,"Win") -> 0 | E14: =COUNTIFS('Bet Log'!B4:B203,"MLB",'Bet Log'!I4:I203,"Loss") -> 0 | F14: =IFERROR(COUNTIFS('Bet Log'!B4:B203,"MLB",'Bet Log'!I4:I203,"Win")/(COUNTIFS('Bet Log'!B4:B203,"MLB",'Bet Log'!I4:I203,"Win")+COUNTIFS('Bet Log'!B4:B203,"MLB",'Bet Log'!I4:I203,"Loss")),"-") -> - | G14: =SUMIFS('Bet Log'!H4:H203,'Bet Log'!B4:B203,"MLB",'Bet Log'!I4:I203,"<>Pending") -> 0 | H14: =SUMIFS('Bet Log'!J4:J203,'Bet Log'!B4:B203,"MLB",'Bet Log'!I4:I203,"<>Pending") -> 0
B15: NHL | C15: =COUNTIFS('Bet Log'!B4:B203,"NHL",'Bet Log'!I4:I203,"<>",'Bet Log'!I4:I203,"<>Pending") -> 0 | D15: =COUNTIFS('Bet Log'!B4:B203,"NHL",'Bet Log'!I4:I203,"Win") -> 0 | E15: =COUNTIFS('Bet Log'!B4:B203,"NHL",'Bet Log'!I4:I203,"Loss") -> 0 | F15: =IFERROR(COUNTIFS('Bet Log'!B4:B203,"NHL",'Bet Log'!I4:I203,"Win")/(COUNTIFS('Bet Log'!B4:B203,"NHL",'Bet Log'!I4:I203,"Win")+COUNTIFS('Bet Log'!B4:B203,"NHL",'Bet Log'!I4:I203,"Loss")),"-") -> - | G15: =SUMIFS('Bet Log'!H4:H203,'Bet Log'!B4:B203,"NHL",'Bet Log'!I4:I203,"<>Pending") -> 0 | H15: =SUMIFS('Bet Log'!J4:J203,'Bet Log'!B4:B203,"NHL",'Bet Log'!I4:I203,"<>Pending") -> 0
B17: PERFORMANCE BY BET TYPE
B18: Bet Type | C18: Bets | D18: Wins | E18: Losses | F18: Win% | G18: Wagered ($) | H18: Net P&L ($)
B19: Spread | C19: =COUNTIFS('Bet Log'!D4:D203,"Spread",'Bet Log'!I4:I203,"<>",'Bet Log'!I4:I203,"<>Pending") -> 0 | D19: =COUNTIFS('Bet Log'!D4:D203,"Spread",'Bet Log'!I4:I203,"Win") -> 0 | E19: =COUNTIFS('Bet Log'!D4:D203,"Spread",'Bet Log'!I4:I203,"Loss") -> 0 | F19: =IFERROR(COUNTIFS('Bet Log'!D4:D203,"Spread",'Bet Log'!I4:I203,"Win")/(COUNTIFS('Bet Log'!D4:D203,"Spread",'Bet Log'!I4:I203,"Win")+COUNTIFS('Bet Log'!D4:D203,"Spread",'Bet Log'!I4:I203,"Loss")),"-") -> - | G19: =SUMIFS('Bet Log'!H4:H203,'Bet Log'!D4:D203,"Spread",'Bet Log'!I4:I203,"<>Pending") -> 0 | H19: =SUMIFS('Bet Log'!J4:J203,'Bet Log'!D4:D203,"Spread",'Bet Log'!I4:I203,"<>Pending") -> 0
B20: Moneyline | C20: =COUNTIFS('Bet Log'!D4:D203,"Moneyline",'Bet Log'!I4:I203,"<>",'Bet Log'!I4:I203,"<>Pending") -> 0 | D20: =COUNTIFS('Bet Log'!D4:D203,"Moneyline",'Bet Log'!I4:I203,"Win") -> 0 | E20: =COUNTIFS('Bet Log'!D4:D203,"Moneyline",'Bet Log'!I4:I203,"Loss") -> 0 | F20: =IFERROR(COUNTIFS('Bet Log'!D4:D203,"Moneyline",'Bet Log'!I4:I203,"Win")/(COUNTIFS('Bet Log'!D4:D203,"Moneyline",'Bet Log'!I4:I203,"Win")+COUNTIFS('Bet Log'!D4:D203,"Moneyline",'Bet Log'!I4:I203,"Loss")),"-") -> - | G20: =SUMIFS('Bet Log'!H4:H203,'Bet Log'!D4:D203,"Moneyline",'Bet Log'!I4:I203,"<>Pending") -> 0 | H20: =SUMIFS('Bet Log'!J4:J203,'Bet Log'!D4:D203,"Moneyline",'Bet Log'!I4:I203,"<>Pending") -> 0
B21: Total (Over) | C21: =COUNTIFS('Bet Log'!D4:D203,"Total (Over)",'Bet Log'!I4:I203,"<>",'Bet Log'!I4:I203,"<>Pending") -> 0 | D21: =COUNTIFS('Bet Log'!D4:D203,"Total (Over)",'Bet Log'!I4:I203,"Win") -> 0 | E21: =COUNTIFS('Bet Log'!D4:D203,"Total (Over)",'Bet Log'!I4:I203,"Loss") -> 0 | F21: =IFERROR(COUNTIFS('Bet Log'!D4:D203,"Total (Over)",'Bet Log'!I4:I203,"Win")/(COUNTIFS('Bet Log'!D4:D203,"Total (Over)",'Bet Log'!I4:I203,"Win")+COUNTIFS('Bet Log'!D4:D203,"Total (Over)",'Bet Log'!I4:I203,"Loss")),"-") -> - | G21: =SUMIFS('Bet Log'!H4:H203,'Bet Log'!D4:D203,"Total (Over)",'Bet Log'!I4:I203,"<>Pending") -> 0 | H21: =SUMIFS('Bet Log'!J4:J203,'Bet Log'!D4:D203,"Total (Over)",'Bet Log'!I4:I203,"<>Pending") -> 0
B22: Total (Under) | C22: =COUNTIFS('Bet Log'!D4:D203,"Total (Under)",'Bet Log'!I4:I203,"<>",'Bet Log'!I4:I203,"<>Pending") -> 0 | D22: =COUNTIFS('Bet Log'!D4:D203,"Total (Under)",'Bet Log'!I4:I203,"Win") -> 0 | E22: =COUNTIFS('Bet Log'!D4:D203,"Total (Under)",'Bet Log'!I4:I203,"Loss") -> 0 | F22: =IFERROR(COUNTIFS('Bet Log'!D4:D203,"Total (Under)",'Bet Log'!I4:I203,"Win")/(COUNTIFS('Bet Log'!D4:D203,"Total (Under)",'Bet Log'!I4:I203,"Win")+COUNTIFS('Bet Log'!D4:D203,"Total (Under)",'Bet Log'!I4:I203,"Loss")),"-") -> - | G22: =SUMIFS('Bet Log'!H4:H203,'Bet Log'!D4:D203,"Total (Under)",'Bet Log'!I4:I203,"<>Pending") -> 0 | H22: =SUMIFS('Bet Log'!J4:J203,'Bet Log'!D4:D203,"Total (Under)",'Bet Log'!I4:I203,"<>Pending") -> 0
B23: Parlay | C23: =COUNTIFS('Bet Log'!D4:D203,"Parlay",'Bet Log'!I4:I203,"<>",'Bet Log'!I4:I203,"<>Pending") -> 0 | D23: =COUNTIFS('Bet Log'!D4:D203,"Parlay",'Bet Log'!I4:I203,"Win") -> 0 | E23: =COUNTIFS('Bet Log'!D4:D203,"Parlay",'Bet Log'!I4:I203,"Loss") -> 0 | F23: =IFERROR(COUNTIFS('Bet Log'!D4:D203,"Parlay",'Bet Log'!I4:I203,"Win")/(COUNTIFS('Bet Log'!D4:D203,"Parlay",'Bet Log'!I4:I203,"Win")+COUNTIFS('Bet Log'!D4:D203,"Parlay",'Bet Log'!I4:I203,"Loss")),"-") -> - | G23: =SUMIFS('Bet Log'!H4:H203,'Bet Log'!D4:D203,"Parlay",'Bet Log'!I4:I203,"<>Pending") -> 0 | H23: =SUMIFS('Bet Log'!J4:J203,'Bet Log'!D4:D203,"Parlay",'Bet Log'!I4:I203,"<>Pending") -> 0
B24: Prop | C24: =COUNTIFS('Bet Log'!D4:D203,"Prop",'Bet Log'!I4:I203,"<>",'Bet Log'!I4:I203,"<>Pending") -> 0 | D24: =COUNTIFS('Bet Log'!D4:D203,"Prop",'Bet Log'!I4:I203,"Win") -> 0 | E24: =COUNTIFS('Bet Log'!D4:D203,"Prop",'Bet Log'!I4:I203,"Loss") -> 0 | F24: =IFERROR(COUNTIFS('Bet Log'!D4:D203,"Prop",'Bet Log'!I4:I203,"Win")/(COUNTIFS('Bet Log'!D4:D203,"Prop",'Bet Log'!I4:I203,"Win")+COUNTIFS('Bet Log'!D4:D203,"Prop",'Bet Log'!I4:I203,"Loss")),"-") -> - | G24: =SUMIFS('Bet Log'!H4:H203,'Bet Log'!D4:D203,"Prop",'Bet Log'!I4:I203,"<>Pending") -> 0 | H24: =SUMIFS('Bet Log'!J4:J203,'Bet Log'!D4:D203,"Prop",'Bet Log'!I4:I203,"<>Pending") -> 0
B25: Futures | C25: =COUNTIFS('Bet Log'!D4:D203,"Futures",'Bet Log'!I4:I203,"<>",'Bet Log'!I4:I203,"<>Pending") -> 0 | D25: =COUNTIFS('Bet Log'!D4:D203,"Futures",'Bet Log'!I4:I203,"Win") -> 0 | E25: =COUNTIFS('Bet Log'!D4:D203,"Futures",'Bet Log'!I4:I203,"Loss") -> 0 | F25: =IFERROR(COUNTIFS('Bet Log'!D4:D203,"Futures",'Bet Log'!I4:I203,"Win")/(COUNTIFS('Bet Log'!D4:D203,"Futures",'Bet Log'!I4:I203,"Win")+COUNTIFS('Bet Log'!D4:D203,"Futures",'Bet Log'!I4:I203,"Loss")),"-") -> - | G25: =SUMIFS('Bet Log'!H4:H203,'Bet Log'!D4:D203,"Futures",'Bet Log'!I4:I203,"<>Pending") -> 0 | H25: =SUMIFS('Bet Log'!J4:J203,'Bet Log'!D4:D203,"Futures",'Bet Log'!I4:I203,"<>Pending") -> 0

Sheet Bet Log
A1: BET THE FARM — MASTER BET TRACKER
A2: Starting Bankroll → | K2: 1000 | L2: ← Set your starting bankroll here (blue = editable)
A3: Date | B3: Sport | C3: Matchup | D3: Bet Type | E3: Pick / Side | F3: Line | G3: Odds | H3: Stake ($) | I3: Result | J3: Net P&L ($) | K3: Balance ($) | L3: Sportsbook | M3: Notes
J4: =IF(OR(H4="",I4="",I4="Pending"),"",IF(I4="Win",IF(G4>=100,H4*(G4/100),H4*(100/ABS(G4))),IF(I4="Loss",-H4,IF(I4="Push",0,"")))) | K4: =IF(H4="","",K2+IF(J4="",0,J4))
J5: =IF(OR(H5="",I5="",I5="Pending"),"",IF(I5="Win",IF(G5>=100,H5*(G5/100),H5*(100/ABS(G5))),IF(I5="Loss",-H5,IF(I5="Push",0,"")))) | K5: =IF(H5="","",IF(K4="",K2,K4)+IF(J5="",0,J5))
J6: =IF(OR(H6="",I6="",I6="Pending"),"",IF(I6="Win",IF(G6>=100,H6*(G6/100),H6*(100/ABS(G6))),IF(I6="Loss",-H6,IF(I6="Push",0,"")))) | K6: =IF(H6="","",IF(K5="",K2,K5)+IF(J6="",0,J6))
J7: =IF(OR(H7="",I7="",I7="Pending"),"",IF(I7="Win",IF(G7>=100,H7*(G7/100),H7*(100/ABS(G7))),IF(I7="Loss",-H7,IF(I7="Push",0,"")))) | K7: =IF(H7="","",IF(K6="",K2,K6)+IF(J7="",0,J7))
J8: =IF(OR(H8="",I8="",I8="Pending"),"",IF(I8="Win",IF(G8>=100,H8*(G8/100),H8*(100/ABS(G8))),IF(I8="Loss",-H8,IF(I8="Push",0,"")))) | K8: =IF(H8="","",IF(K7="",K2,K7)+IF(J8="",0,J8))
J9: =IF(OR(H9="",I9="",I9="Pending"),"",IF(I9="Win",IF(G9>=100,H9*(G9/100),H9*(100/ABS(G9))),IF(I9="Loss",-H9,IF(I9="Push",0,"")))) | K9: =IF(H9="","",IF(K8="",K2,K8)+IF(J9="",0,J9))
J10: =IF(OR(H10="",I10="",I10="Pending"),"",IF(I10="Win",IF(G10>=100,H10*(G10/100),H10*(100/ABS(G10))),IF(I10="Loss",-H10,IF(I10="Push",0,"")))) | K10: =IF(H10="","",IF(K9="",K2,K9)+IF(J10="",0,J10))
J11: =IF(OR(H11="",I11="",I11="Pending"),"",IF(I11="Win",IF(G11>=100,H11*(G11/100),H11*(100/ABS(G11))),IF(I11="Loss",-H11,IF(I11="Push",0,"")))) | K11: =IF(H11="","",IF(K10="",K2,K10)+IF(J11="",0,J11))
J12: =IF(OR(H12="",I12="",I12="Pending"),"",IF(I12="Win",IF(G12>=100,H12*(G12/100),H12*(100/ABS(G12))),IF(I12="Loss",-H12,IF(I12="Push",0,"")))) | K12: =IF(H12="","",IF(K11="",K2,K11)+IF(J12="",0,J12))
J13: =IF(OR(H13="",I13="",I13="Pending"),"",IF(I13="Win",IF(G13>=100,H13*(G13/100),H13*(100/ABS(G13))),IF(I13="Loss",-H13,IF(I13="Push",0,"")))) | K13: =IF(H13="","",IF(K12="",K2,K12)+IF(J13="",0,J13))
J14: =IF(OR(H14="",I14="",I14="Pending"),"",IF(I14="Win",IF(G14>=100,H14*(G14/100),H14*(100/ABS(G14))),IF(I14="Loss",-H14,IF(I14="Push",0,"")))) | K14: =IF(H14="","",IF(K13="",K2,K13)+IF(J14="",0,J14))
J15: =IF(OR(H15="",I15="",I15="Pending"),"",IF(I15="Win",IF(G15>=100,H15*(G15/100),H15*(100/ABS(G15))),IF(I15="Loss",-H15,IF(I15="Push",0,"")))) | K15: =IF(H15="","",IF(K14="",K2,K14)+IF(J15="",0,J15))
J16: =IF(OR(H16="",I16="",I16="Pending"),"",IF(I16="Win",IF(G16>=100,H16*(G16/100),H16*(100/ABS(G16))),IF(I16="Loss",-H16,IF(I16="Push",0,"")))) | K16: =IF(H16="","",IF(K15="",K2,K15)+IF(J16="",0,J16))
J17: =IF(OR(H17="",I17="",I17="Pending"),"",IF(I17="Win",IF(G17>=100,H17*(G17/100),H17*(100/ABS(G17))),IF(I17="Loss",-H17,IF(I17="Push",0,"")))) | K17: =IF(H17="","",IF(K16="",K2,K16)+IF(J17="",0,J17))
J18: =IF(OR(H18="",I18="",I18="Pending"),"",IF(I18="Win",IF(G18>=100,H18*(G18/100),H18*(100/ABS(G18))),IF(I18="Loss",-H18,IF(I18="Push",0,"")))) | K18: =IF(H18="","",IF(K17="",K2,K17)+IF(J18="",0,J18))
J19: =IF(OR(H19="",I19="",I19="Pending"),"",IF(I19="Win",IF(G19>=100,H19*(G19/100),H19*(100/ABS(G19))),IF(I19="Loss",-H19,IF(I19="Push",0,"")))) | K19: =IF(H19="","",IF(K18="",K2,K18)+IF(J19="",0,J19))
J20: =IF(OR(H20="",I20="",I20="Pending"),"",IF(I20="Win",IF(G20>=100,H20*(G20/100),H20*(100/ABS(G20))),IF(I20="Loss",-H20,IF(I20="Push",0,"")))) | K20: =IF(H20="","",IF(K19="",K2,K19)+IF(J20="",0,J20))
J21: =IF(OR(H21="",I21="",I21="Pending"),"",IF(I21="Win",IF(G21>=100,H21*(G21/100),H21*(100/ABS(G21))),IF(I21="Loss",-H21,IF(I21="Push",0,"")))) | K21: =IF(H21="","",IF(K20="",K2,K20)+IF(J21="",0,J21))
J22: =IF(OR(H22="",I22="",I22="Pending"),"",IF(I22="Win",IF(G22>=100,H22*(G22/100),H22*(100/ABS(G22))),IF(I22="Loss",-H22,IF(I22="Push",0,"")))) | K22: =IF(H22="","",IF(K21="",K2,K21)+IF(J22="",0,J22))
J23: =IF(OR(H23="",I23="",I23="Pending"),"",IF(I23="Win",IF(G23>=100,H23*(G23/100),H23*(100/ABS(G23))),IF(I23="Loss",-H23,IF(I23="Push",0,"")))) | K23: =IF(H23="","",IF(K22="",K2,K22)+IF(J23="",0,J23))
J24: =IF(OR(H24="",I24="",I24="Pending"),"",IF(I24="Win",IF(G24>=100,H24*(G24/100),H24*(100/ABS(G24))),IF(I24="Loss",-H24,IF(I24="Push",0,"")))) | K24: =IF(H24="","",IF(K23="",K2,K23)+IF(J24="",0,J24))
J25: =IF(OR(H25="",I25="",I25="Pending"),"",IF(I25="Win",IF(G25>=100,H25*(G25/100),H25*(100/ABS(G25))),IF(I25="Loss",-H25,IF(I25="Push",0,"")))) | K25: =IF(H25="","",IF(K24="",K2,K24)+IF(J25="",0,J25))
J26: =IF(OR(H26="",I26="",I26="Pending"),"",IF(I26="Win",IF(G26>=100,H26*(G26/100),H26*(100/ABS(G26))),IF(I26="Loss",-H26,IF(I26="Push",0,"")))) | K26: =IF(H26="","",IF(K25="",K2,K25)+IF(J26="",0,J26))
J27: =IF(OR(H27="",I27="",I27="Pending"),"",IF(I27="Win",IF(G27>=100,H27*(G27/100),H27*(100/ABS(G27))),IF(I27="Loss",-H27,IF(I27="Push",0,"")))) | K27: =IF(H27="","",IF(K26="",K2,K26)+IF(J27="",0,J27))
J28: =IF(OR(H28="",I28="",I28="Pending"),"",IF(I28="Win",IF(G28>=100,H28*(G28/100),H28*(100/ABS(G28))),IF(I28="Loss",-H28,IF(I28="Push",0,"")))) | K28: =IF(H28="","",IF(K27="",K2,K27)+IF(J28="",0,J28))
J29: =IF(OR(H29="",I29="",I29="Pending"),"",IF(I29="Win",IF(G29>=100,H29*(G29/100),H29*(100/ABS(G29))),IF(I29="Loss",-H29,IF(I29="Push",0,"")))) | K29: =IF(H29="","",IF(K28="",K2,K28)+IF(J29="",0,J29))
J30: =IF(OR(H30="",I30="",I30="Pending"),"",IF(I30="Win",IF(G30>=100,H30*(G30/100),H30*(100/ABS(G30))),IF(I30="Loss",-H30,IF(I30="Push",0,"")))) | K30: =IF(H30="","",IF(K29="",K2,K29)+IF(J30="",0,J30))
J31: =IF(OR(H31="",I31="",I31="Pending"),"",IF(I31="Win",IF(G31>=100,H31*(G31/100),H31*(100/ABS(G31))),IF(I31="Loss",-H31,IF(I31="Push",0,"")))) | K31: =IF(H31="","",IF(K30="",K2,K30)+IF(J31="",0,J31))
J32: =IF(OR(H32="",I32="",I32="Pending"),"",IF(I32="Win",IF(G32>=100,H32*(G32/100),H32*(100/ABS(G32))),IF(I32="Loss",-H32,IF(I32="Push",0,"")))) | K32: =IF(H32="","",IF(K31="",K2,K31)+IF(J32="",0,J32))
J33: =IF(OR(H33="",I33="",I33="Pending"),"",IF(I33="Win",IF(G33>=100,H33*(G33/100),H33*(100/ABS(G33))),IF(I33="Loss",-H33,IF(I33="Push",0,"")))) | K33: =IF(H33="","",IF(K32="",K2,K32)+IF(J33="",0,J33))
J34: =IF(OR(H34="",I34="",I34="Pending"),"",IF(I34="Win",IF(G34>=100,H34*(G34/100),H34*(100/ABS(G34))),IF(I34="Loss",-H34,IF(I34="Push",0,"")))) | K34: =IF(H34="","",IF(K33="",K2,K33)+IF(J34="",0,J34))
J35: =IF(OR(H35="",I35="",I35="Pending"),"",IF(I35="Win",IF(G35>=100,H35*(G35/100),H35*(100/ABS(G35))),IF(I35="Loss",-H35,IF(I35="Push",0,"")))) | K35: =IF(H35="","",IF(K34="",K2,K34)+IF(J35="",0,J35))
J36: =IF(OR(H36="",I36="",I36="Pending"),"",IF(I36="Win",IF(G36>=100,H36*(G36/100),H36*(100/ABS(G36))),IF(I36="Loss",-H36,IF(I36="Push",0,"")))) | K36: =IF(H36="","",IF(K35="",K2,K35)+IF(J36="",0,J36))
J37: =IF(OR(H37="",I37="",I37="Pending"),"",IF(I37="Win",IF(G37>=100,H37*(G37/100),H37*(100/ABS(G37))),IF(I37="Loss",-H37,IF(I37="Push",0,"")))) | K37: =IF(H37="","",IF(K36="",K2,K36)+IF(J37="",0,J37))
J38: =IF(OR(H38="",I38="",I38="Pending"),"",IF(I38="Win",IF(G38>=100,H38*(G38/100),H38*(100/ABS(G38))),IF(I38="Loss",-H38,IF(I38="Push",0,"")))) | K38: =IF(H38="","",IF(K37="",K2,K37)+IF(J38="",0,J38))
J39: =IF(OR(H39="",I39="",I39="Pending"),"",IF(I39="Win",IF(G39>=100,H39*(G39/100),H39*(100/ABS(G39))),IF(I39="Loss",-H39,IF(I39="Push",0,"")))) | K39: =IF(H39="","",IF(K38="",K2,K38)+IF(J39="",0,J39))
J40: =IF(OR(H40="",I40="",I40="Pending"),"",IF(I40="Win",IF(G40>=100,H40*(G40/100),H40*(100/ABS(G40))),IF(I40="Loss",-H40,IF(I40="Push",0,"")))) | K40: =IF(H40="","",IF(K39="",K2,K39)+IF(J40="",0,J40))
...

Sheet How To Use
B1: HOW TO USE — BET THE FARM TRACKER
B3: GETTING STARTED
B4: Step 1 — Set Your Bankroll | C4: Go to the Bet Log sheet. In cell K2 (the blue cell), enter your group's starting bankroll. Default is $1,000. This anchors all running balance calculations.
B5: Step 2 — Log Every Bet | C5: Fill in one row per bet: • Date — when you placed the bet • Sport — dropdown (CBB, CFB, NFL, NBA, MLB, NHL) • Matchup — e.g. 'Kansas @ Duke' • Bet Type — dropdown (Spread, ML, Total, Parlay, Prop, etc.) • Pick / Side — what you bet, e.g. 'Kansas -3.5' • Line — the spread or total number (e.g. -3.5 or 48.5) • Odds — American odds (e.g. -110 or +150) • Stake — dollar amount wagered • Result — Win / Loss / Push / Pending • Sportsbook — where you placed the bet
B6: Step 3 — Track Results | C6: Once a game is final, update the Result to Win, Loss, or Push. Net P&L and Running Balance auto-calculate. Rows turn green for wins, red for losses.
B7: Step 4 — Check the Dashboard | C7: The Dashboard tab shows overall W/L/Win%/ROI/P&L plus breakdowns by Sport and Bet Type. The bankroll chart updates automatically as you log results.
B8: UNDERSTANDING AMERICAN ODDS
B9: -110 | C9: Standard vig on most spread/total bets. Bet $110 to win $100. Break-even win rate: 52.4%.
B10: -200 | C10: Big favorite on moneyline. Bet $200 to win $100. Need 66.7% win rate to profit.
B11: +150 | C11: Underdog on moneyline. Bet $100 to win $150. Only need 40% win rate to profit.
B12: TIPS FOR FINDING AN EDGE
B13: Shop lines | C13: Always compare FanDuel, DraftKings, BetMGM, and Caesars. Half a point on a spread makes a real difference over a season.
B14: Track closing line value | C14: If you consistently beat the line at close, you're a sharp bettor. It's the best long-term skill indicator.
B15: College Basketball | C15: Focus on pace, adjusted efficiency (kenpom.com), home/away splits, and conference familiarity. Fade public teams in neutral-site games.
B16: College Football | C16: Situational spots: look-ahead games, revenge games, weather, travel distance, and teams playing their 3rd road game in 4 weeks.
B17: NFL | C17: Prime-time inflated lines, divisional game overs/unders, injury reports (especially QB, OL), and rest advantages.
B18: NBA | C18: Back-to-backs, rest advantages, pace mismatches for totals, and player prop value on high-usage players.
B19: MLB | C19: Starting pitcher matchup, bullpen depth, park factors, weather (wind direction/speed), and team totals on run lines.
B20: NHL | C20: Goalie confirmations before betting, puck line value on heavy favorites, and road dogs in divisional games.
B21: BANKROLL MANAGEMENT
B22: Unit sizing | C22: Bet 1–3% of bankroll per game. A 'unit' is typically 1% of your starting bankroll.
B23: Never chase losses | C23: Stick to your unit size even after a bad run. Variance is real — protect the bankroll.
B24: Parlays | C24: Fun but high-vig. Keep parlay exposure to <10% of bets. Single-game +EV bets build bankroll more reliably.
